{
 "cells": [
  {
   "cell_type": "code",
   "execution_count": 13,
   "metadata": {},
   "outputs": [],
   "source": [
    "from keras.models import load_model\n",
    "import numpy as np\n",
    "from tensorflow.keras.preprocessing import image\n",
    "from tensorflow.keras.applications.mobilenet import preprocess_input\n",
    "TEST_DIR = r'D:\\giga projects\\three_faces\\validation_dataset\\test_elon1'\n",
    "\n",
    "img = image.load_img(TEST_DIR, target_size=(224, 224))\n",
    "img_array = image.img_to_array(img)\n",
    "exp_img_arr = np.expand_dims(img_array, axis=0)\n",
    "preprocessed_img = preprocess_input(exp_img_arr)\n"
   ]
  },
  {
   "cell_type": "code",
   "execution_count": 14,
   "metadata": {},
   "outputs": [],
   "source": [
    "model = load_model('D:\\giga projects\\model\\model.h5')"
   ]
  },
  {
   "cell_type": "code",
   "execution_count": 10,
   "metadata": {},
   "outputs": [],
   "source": [
    "prediction = model.predict(preprocessed_img)\n",
    "print(prediction)\n",
    "print()"
   ]
  },
  {
   "cell_type": "code",
   "execution_count": 12,
   "metadata": {},
   "outputs": [
    {
     "name": "stdout",
     "output_type": "stream",
     "text": [
      "Epoch 1/5\n"
     ]
    },
    {
     "ename": "ValueError",
     "evalue": "in user code:\n\n    File \"c:\\Users\\user\\AppData\\Local\\Programs\\Python\\Python311\\Lib\\site-packages\\keras\\engine\\training.py\", line 1284, in train_function  *\n        return step_function(self, iterator)\n    File \"c:\\Users\\user\\AppData\\Local\\Programs\\Python\\Python311\\Lib\\site-packages\\keras\\engine\\training.py\", line 1268, in step_function  **\n        outputs = model.distribute_strategy.run(run_step, args=(data,))\n    File \"c:\\Users\\user\\AppData\\Local\\Programs\\Python\\Python311\\Lib\\site-packages\\keras\\engine\\training.py\", line 1249, in run_step  **\n        outputs = model.train_step(data)\n    File \"c:\\Users\\user\\AppData\\Local\\Programs\\Python\\Python311\\Lib\\site-packages\\keras\\engine\\training.py\", line 1050, in train_step\n        y_pred = self(x, training=True)\n    File \"c:\\Users\\user\\AppData\\Local\\Programs\\Python\\Python311\\Lib\\site-packages\\keras\\utils\\traceback_utils.py\", line 70, in error_handler\n        raise e.with_traceback(filtered_tb) from None\n    File \"c:\\Users\\user\\AppData\\Local\\Programs\\Python\\Python311\\Lib\\site-packages\\keras\\engine\\input_spec.py\", line 280, in assert_input_compatibility\n        raise ValueError(\n\n    ValueError: Exception encountered when calling layer 'mobilenet_1.00_224' (type Functional).\n    \n    Input 0 of layer \"conv1\" is incompatible with the layer: expected axis -1 of input shape to have value 3, but received input with shape (None, 224, 224, 1)\n    \n    Call arguments received by layer 'mobilenet_1.00_224' (type Functional):\n      • inputs=tf.Tensor(shape=(None, 224, 224, 1), dtype=float32)\n      • training=True\n      • mask=None\n",
     "output_type": "error",
     "traceback": [
      "\u001b[1;31m---------------------------------------------------------------------------\u001b[0m",
      "\u001b[1;31mValueError\u001b[0m                                Traceback (most recent call last)",
      "Cell \u001b[1;32mIn[12], line 1\u001b[0m\n\u001b[1;32m----> 1\u001b[0m model\u001b[39m.\u001b[39;49mfit(X, y, validation_split\u001b[39m=\u001b[39;49m\u001b[39m0.1\u001b[39;49m, batch_size\u001b[39m=\u001b[39;49m\u001b[39m16\u001b[39;49m, epochs\u001b[39m=\u001b[39;49m\u001b[39m5\u001b[39;49m, verbose\u001b[39m=\u001b[39;49m\u001b[39m1\u001b[39;49m)\n",
      "File \u001b[1;32mc:\\Users\\user\\AppData\\Local\\Programs\\Python\\Python311\\Lib\\site-packages\\keras\\utils\\traceback_utils.py:70\u001b[0m, in \u001b[0;36mfilter_traceback.<locals>.error_handler\u001b[1;34m(*args, **kwargs)\u001b[0m\n\u001b[0;32m     67\u001b[0m     filtered_tb \u001b[39m=\u001b[39m _process_traceback_frames(e\u001b[39m.\u001b[39m__traceback__)\n\u001b[0;32m     68\u001b[0m     \u001b[39m# To get the full stack trace, call:\u001b[39;00m\n\u001b[0;32m     69\u001b[0m     \u001b[39m# `tf.debugging.disable_traceback_filtering()`\u001b[39;00m\n\u001b[1;32m---> 70\u001b[0m     \u001b[39mraise\u001b[39;00m e\u001b[39m.\u001b[39mwith_traceback(filtered_tb) \u001b[39mfrom\u001b[39;00m \u001b[39mNone\u001b[39;00m\n\u001b[0;32m     71\u001b[0m \u001b[39mfinally\u001b[39;00m:\n\u001b[0;32m     72\u001b[0m     \u001b[39mdel\u001b[39;00m filtered_tb\n",
      "File \u001b[1;32m~\\AppData\\Local\\Temp\\__autograph_generated_file5op100bo.py:15\u001b[0m, in \u001b[0;36mouter_factory.<locals>.inner_factory.<locals>.tf__train_function\u001b[1;34m(iterator)\u001b[0m\n\u001b[0;32m     13\u001b[0m \u001b[39mtry\u001b[39;00m:\n\u001b[0;32m     14\u001b[0m     do_return \u001b[39m=\u001b[39m \u001b[39mTrue\u001b[39;00m\n\u001b[1;32m---> 15\u001b[0m     retval_ \u001b[39m=\u001b[39m ag__\u001b[39m.\u001b[39mconverted_call(ag__\u001b[39m.\u001b[39mld(step_function), (ag__\u001b[39m.\u001b[39mld(\u001b[39mself\u001b[39m), ag__\u001b[39m.\u001b[39mld(iterator)), \u001b[39mNone\u001b[39;00m, fscope)\n\u001b[0;32m     16\u001b[0m \u001b[39mexcept\u001b[39;00m:\n\u001b[0;32m     17\u001b[0m     do_return \u001b[39m=\u001b[39m \u001b[39mFalse\u001b[39;00m\n",
      "\u001b[1;31mValueError\u001b[0m: in user code:\n\n    File \"c:\\Users\\user\\AppData\\Local\\Programs\\Python\\Python311\\Lib\\site-packages\\keras\\engine\\training.py\", line 1284, in train_function  *\n        return step_function(self, iterator)\n    File \"c:\\Users\\user\\AppData\\Local\\Programs\\Python\\Python311\\Lib\\site-packages\\keras\\engine\\training.py\", line 1268, in step_function  **\n        outputs = model.distribute_strategy.run(run_step, args=(data,))\n    File \"c:\\Users\\user\\AppData\\Local\\Programs\\Python\\Python311\\Lib\\site-packages\\keras\\engine\\training.py\", line 1249, in run_step  **\n        outputs = model.train_step(data)\n    File \"c:\\Users\\user\\AppData\\Local\\Programs\\Python\\Python311\\Lib\\site-packages\\keras\\engine\\training.py\", line 1050, in train_step\n        y_pred = self(x, training=True)\n    File \"c:\\Users\\user\\AppData\\Local\\Programs\\Python\\Python311\\Lib\\site-packages\\keras\\utils\\traceback_utils.py\", line 70, in error_handler\n        raise e.with_traceback(filtered_tb) from None\n    File \"c:\\Users\\user\\AppData\\Local\\Programs\\Python\\Python311\\Lib\\site-packages\\keras\\engine\\input_spec.py\", line 280, in assert_input_compatibility\n        raise ValueError(\n\n    ValueError: Exception encountered when calling layer 'mobilenet_1.00_224' (type Functional).\n    \n    Input 0 of layer \"conv1\" is incompatible with the layer: expected axis -1 of input shape to have value 3, but received input with shape (None, 224, 224, 1)\n    \n    Call arguments received by layer 'mobilenet_1.00_224' (type Functional):\n      • inputs=tf.Tensor(shape=(None, 224, 224, 1), dtype=float32)\n      • training=True\n      • mask=None\n"
     ]
    }
   ],
   "source": []
  },
  {
   "cell_type": "code",
   "execution_count": 5,
   "metadata": {},
   "outputs": [
    {
     "name": "stdout",
     "output_type": "stream",
     "text": [
      "1/1 [==============================] - 0s 170ms/step - loss: 0.0000e+00 - accuracy: 0.0000e+00\n"
     ]
    },
    {
     "data": {
      "text/plain": [
       "[0.0, 0.0]"
      ]
     },
     "execution_count": 5,
     "metadata": {},
     "output_type": "execute_result"
    }
   ],
   "source": []
  },
  {
   "cell_type": "code",
   "execution_count": null,
   "metadata": {},
   "outputs": [],
   "source": []
  },
  {
   "cell_type": "code",
   "execution_count": 6,
   "metadata": {},
   "outputs": [],
   "source": []
  },
  {
   "cell_type": "code",
   "execution_count": 17,
   "metadata": {},
   "outputs": [
    {
     "name": "stdout",
     "output_type": "stream",
     "text": [
      "(224, 224, 1)\n"
     ]
    },
    {
     "ename": "ValueError",
     "evalue": "in user code:\n\n    File \"c:\\Users\\user\\AppData\\Local\\Programs\\Python\\Python311\\Lib\\site-packages\\keras\\engine\\training.py\", line 2169, in predict_function  *\n        return step_function(self, iterator)\n    File \"c:\\Users\\user\\AppData\\Local\\Programs\\Python\\Python311\\Lib\\site-packages\\keras\\engine\\training.py\", line 2155, in step_function  **\n        outputs = model.distribute_strategy.run(run_step, args=(data,))\n    File \"c:\\Users\\user\\AppData\\Local\\Programs\\Python\\Python311\\Lib\\site-packages\\keras\\engine\\training.py\", line 2143, in run_step  **\n        outputs = model.predict_step(data)\n    File \"c:\\Users\\user\\AppData\\Local\\Programs\\Python\\Python311\\Lib\\site-packages\\keras\\engine\\training.py\", line 2111, in predict_step\n        return self(x, training=False)\n    File \"c:\\Users\\user\\AppData\\Local\\Programs\\Python\\Python311\\Lib\\site-packages\\keras\\utils\\traceback_utils.py\", line 70, in error_handler\n        raise e.with_traceback(filtered_tb) from None\n    File \"c:\\Users\\user\\AppData\\Local\\Programs\\Python\\Python311\\Lib\\site-packages\\keras\\engine\\input_spec.py\", line 253, in assert_input_compatibility\n        raise ValueError(\n\n    ValueError: Exception encountered when calling layer 'sequential' (type Sequential).\n    \n    Input 0 of layer \"conv2d\" is incompatible with the layer: expected min_ndim=4, found ndim=2. Full shape received: (32, 1)\n    \n    Call arguments received by layer 'sequential' (type Sequential):\n      • inputs=tf.Tensor(shape=(32, 1), dtype=float32)\n      • training=False\n      • mask=None\n",
     "output_type": "error",
     "traceback": [
      "\u001b[1;31m---------------------------------------------------------------------------\u001b[0m",
      "\u001b[1;31mValueError\u001b[0m                                Traceback (most recent call last)",
      "Cell \u001b[1;32mIn[17], line 7\u001b[0m\n\u001b[0;32m      4\u001b[0m ax \u001b[39m=\u001b[39m plt\u001b[39m.\u001b[39msubplot(\u001b[39m4\u001b[39m, \u001b[39m4\u001b[39m, i \u001b[39m+\u001b[39m \u001b[39m1\u001b[39m)\n\u001b[0;32m      5\u001b[0m plt\u001b[39m.\u001b[39mimshow(img, cmap\u001b[39m=\u001b[39m\u001b[39m'\u001b[39m\u001b[39mgray\u001b[39m\u001b[39m'\u001b[39m)\n\u001b[1;32m----> 7\u001b[0m plt\u001b[39m.\u001b[39mtitle(\u001b[39mstr\u001b[39m(gates_or_musk(model\u001b[39m.\u001b[39;49mpredict(img))))\n\u001b[0;32m      9\u001b[0m plt\u001b[39m.\u001b[39maxis(\u001b[39m'\u001b[39m\u001b[39moff\u001b[39m\u001b[39m'\u001b[39m)\n",
      "File \u001b[1;32mc:\\Users\\user\\AppData\\Local\\Programs\\Python\\Python311\\Lib\\site-packages\\keras\\utils\\traceback_utils.py:70\u001b[0m, in \u001b[0;36mfilter_traceback.<locals>.error_handler\u001b[1;34m(*args, **kwargs)\u001b[0m\n\u001b[0;32m     67\u001b[0m     filtered_tb \u001b[39m=\u001b[39m _process_traceback_frames(e\u001b[39m.\u001b[39m__traceback__)\n\u001b[0;32m     68\u001b[0m     \u001b[39m# To get the full stack trace, call:\u001b[39;00m\n\u001b[0;32m     69\u001b[0m     \u001b[39m# `tf.debugging.disable_traceback_filtering()`\u001b[39;00m\n\u001b[1;32m---> 70\u001b[0m     \u001b[39mraise\u001b[39;00m e\u001b[39m.\u001b[39mwith_traceback(filtered_tb) \u001b[39mfrom\u001b[39;00m \u001b[39mNone\u001b[39;00m\n\u001b[0;32m     71\u001b[0m \u001b[39mfinally\u001b[39;00m:\n\u001b[0;32m     72\u001b[0m     \u001b[39mdel\u001b[39;00m filtered_tb\n",
      "File \u001b[1;32m~\\AppData\\Local\\Temp\\__autograph_generated_file3mynl6gj.py:15\u001b[0m, in \u001b[0;36mouter_factory.<locals>.inner_factory.<locals>.tf__predict_function\u001b[1;34m(iterator)\u001b[0m\n\u001b[0;32m     13\u001b[0m \u001b[39mtry\u001b[39;00m:\n\u001b[0;32m     14\u001b[0m     do_return \u001b[39m=\u001b[39m \u001b[39mTrue\u001b[39;00m\n\u001b[1;32m---> 15\u001b[0m     retval_ \u001b[39m=\u001b[39m ag__\u001b[39m.\u001b[39mconverted_call(ag__\u001b[39m.\u001b[39mld(step_function), (ag__\u001b[39m.\u001b[39mld(\u001b[39mself\u001b[39m), ag__\u001b[39m.\u001b[39mld(iterator)), \u001b[39mNone\u001b[39;00m, fscope)\n\u001b[0;32m     16\u001b[0m \u001b[39mexcept\u001b[39;00m:\n\u001b[0;32m     17\u001b[0m     do_return \u001b[39m=\u001b[39m \u001b[39mFalse\u001b[39;00m\n",
      "\u001b[1;31mValueError\u001b[0m: in user code:\n\n    File \"c:\\Users\\user\\AppData\\Local\\Programs\\Python\\Python311\\Lib\\site-packages\\keras\\engine\\training.py\", line 2169, in predict_function  *\n        return step_function(self, iterator)\n    File \"c:\\Users\\user\\AppData\\Local\\Programs\\Python\\Python311\\Lib\\site-packages\\keras\\engine\\training.py\", line 2155, in step_function  **\n        outputs = model.distribute_strategy.run(run_step, args=(data,))\n    File \"c:\\Users\\user\\AppData\\Local\\Programs\\Python\\Python311\\Lib\\site-packages\\keras\\engine\\training.py\", line 2143, in run_step  **\n        outputs = model.predict_step(data)\n    File \"c:\\Users\\user\\AppData\\Local\\Programs\\Python\\Python311\\Lib\\site-packages\\keras\\engine\\training.py\", line 2111, in predict_step\n        return self(x, training=False)\n    File \"c:\\Users\\user\\AppData\\Local\\Programs\\Python\\Python311\\Lib\\site-packages\\keras\\utils\\traceback_utils.py\", line 70, in error_handler\n        raise e.with_traceback(filtered_tb) from None\n    File \"c:\\Users\\user\\AppData\\Local\\Programs\\Python\\Python311\\Lib\\site-packages\\keras\\engine\\input_spec.py\", line 253, in assert_input_compatibility\n        raise ValueError(\n\n    ValueError: Exception encountered when calling layer 'sequential' (type Sequential).\n    \n    Input 0 of layer \"conv2d\" is incompatible with the layer: expected min_ndim=4, found ndim=2. Full shape received: (32, 1)\n    \n    Call arguments received by layer 'sequential' (type Sequential):\n      • inputs=tf.Tensor(shape=(32, 1), dtype=float32)\n      • training=False\n      • mask=None\n"
     ]
    },
    {
     "data": {
      "image/png": "iVBORw0KGgoAAAANSUhEUgAAAEgAAACBCAYAAABjCvw7AAAAOXRFWHRTb2Z0d2FyZQBNYXRwbG90bGliIHZlcnNpb24zLjcuMSwgaHR0cHM6Ly9tYXRwbG90bGliLm9yZy/bCgiHAAAACXBIWXMAAA9hAAAPYQGoP6dpAAAHzElEQVR4nO2cX0iT3x/H35v7Y/6Zc01dkqtMQmJeRPmvQLoYSRnUl0KQugn/YC1KEIkFXXQRuw6p6CaFLIS6kcLqwkwK1FKyUFdiJVk5o8JNM//MvX83Px/cN+v45zenP84LDmPnOc/Oey+enTOeBz4qkoTkj6jDHWC1IwUJkIIESEECpCABUpAAKUiAFCRAChIgBQkIm6ArV65g8+bNiIyMRHZ2Np4/fx6uKH+HYaC+vp46nY43btxgT08PS0tLaTQaOTw8HI44fyUsgrKysuhwOJT3MzMzTE5OpsvlCkecv7LiP7GpqSl0dnbCbrcrfWq1Gna7Ha2trfOeMzk5CZ/Pp7SRkRG8f/8egUAg5HlXXNC3b98wMzODpKSkoP6kpCR4PJ55z3G5XIiLi1NafHw8tm7dii9fvoQ875rYxZxOJ7xer9J6e3tXbG7Nis30X8xmMyIiIjA8PBzUPzw8DIvFMu85er0eer1eee/z+UKacS4rfgXpdDrs3LkTTU1NSl8gEEBTUxNyc3NXOo6YcOwM9fX11Ov1rK2tZW9vL8vKymg0GunxeBZ0/uDgIAFwcHAwxEnDtM2TZHV1Na1WK3U6HbOystjW1rbgc1dSkIpcezftP336hJSUFAwODmLjxo0hnWtN7GLhRAoSIAUJkIIESEECpCABUpAAKUiAFCRAChIgBQmQggRIQQKkIAFSkAApSIAUJEAKEiAFCZCCBEhBAqQgAVKQAClIgBQkQAoSIAUJkIIESEECpCABUpAAKUiAFCRAChIgBQmQggRIQQKkIAFSkAApSIAUJEAKEiAFCZCCBEhBAqQgAVKQAClIgBQkQAoSIAUJkIIESEECpCABUpAAKUiAFCRAChIgBQmQggRIQQIWJcjlciEzMxOxsbFITEzE4cOH8fbt26AxExMTcDgcWL9+PWJiYnDkyJHfqk19/PgRBQUFiIqKQmJiIqqqquD3+5f/bULBYmrp5Ofns6amht3d3ezq6uKBAwdotVo5NjamjCkvL2dKSgqbmprY0dHBnJwc7t69Wznu9/tps9lot9v58uVLNjY20mw20+l0LjjHmimw9PXrVwJgS0sLSXJkZIRarZZ37txRxrjdbgJga2srSbKxsZFqtTqo2tS1a9doMBg4OTm5oHlXUtCy1iCv1wsAMJlMAIDOzk5MT08H1UhMT0+H1WpVaiS2trYiIyMjqExgfn4+fD4fenp65p3n33UUR0dHlxN7USxZUCAQQEVFBfbs2QObzQYA8Hg80Ol0MBqNQWPn1kj0eDzz1lCcPTYf/66juH379qXGXjRLFuRwONDd3Y36+vr/ZZ55CWcdxSUJOn36NO7fv4/m5uagGmIWiwVTU1MYGRkJGj+3RqLFYpm3huLssfnQ6/UwGAxKi42NXUrspbGYBSsQCNDhcDA5OZl9fX2/HZ9dpO/evav0vXnzZt5Fem7l3+vXr9NgMHBiYmJBOVbtLnby5EnGxcXxyZMnHBoaUtr4+Lgypry8nFarlY8fP2ZHRwdzc3OZm5urHJ/d5vft28euri4+fPiQCQkJ/x/bPIB5W01NjTLm169fPHXqFOPj4xkVFcV//vmHQ0NDQZ8zMDDA/fv3c926dTSbzaysrOT09PSCc8g6igJkHcVVxJoU9P3796DXULImBWk0mqDXULImBanV6qDXkM4V8hnWOFKQgDUpyGw2Y9OmTTCbzSGfa03+D1pJ1uQVtJJIQQKkIAFSkIBVK6iwsBAajQYqlQoxMTGorq7GsWPHYDAYYDQaUVxcjLGxMQBAbW0tVCpVUNPpdNi7d+9v/eXl5YsLEvL7BUvgzJkzBMATJ06woaGB6enpBMBt27axra2NT58+ZVpaGouKikiS58+fJwBeuHCBLS0trKiooEaj4a5du1haWhp078rr9S4qy6oUFB0dzYyMDOX969evCYA5OTlK34MHD6hSqfj582dmZmZSo9EEfUZ2djY3bNjAs2fPLivLqvuJjY2N4efPnygoKFD6Xrx4AZVKhYGBAaXPbrdDrVajvb0d7969QyAQwKZNm5CSkoJDhw5hx44d8Pl8uHXrFsxmM2w2G5xOJ8bHxxeVZ9UJ6uvrAwBs2bJF6Zt9nDT3eZhGo4HJZILH44HX60VZWRkaGhpQV1eHQCCA2tpaAEBdXR2am5vhdDpx8+ZNHD9+fHGBlnX9LZNz58798TbubHO73bx06RL1ej2jo6ODzk9ISODVq1ep1Wp5+/ZtpX9qaopms5lRUVFB45uamgiA/f39C84Y1iuosrISbrc7qHV0dAAASkpK4Ha7kZqaqjxOmvu4x+/348ePH7BYLL89StJqtUhISIBWqw2aLzs7GwDQ39+/8JDLuwZCw58W6blPRx49eqQs0oWFhTx48KByzO/3MzIyMugzSPLZs2cEwFevXi04y6oUNLvNl5SU8N69e8o2n56ezvb2diYnJzMyMlLZ5ouLi6lWq2kymehyuWiz2QiARUVF7Ojo4IcPH9jQ0MDU1FTm5eUtKsuqFESSR48eZUREBAEwOjqaly9fZlFREWNiYgiAsbGxHB0dJUlWVFQwPj5eWbdiYmJ48eJF5uXl0WQyUa/XMy0tjVVVVYv+HyRvdwhYddv8akMKEiAFCZCCBEhBAqQgAVKQAClIgBQkQAoSIAUJkIIE/Ad51XCnTGh+XAAAAABJRU5ErkJggg==",
      "text/plain": [
       "<Figure size 640x480 with 1 Axes>"
      ]
     },
     "metadata": {},
     "output_type": "display_data"
    }
   ],
   "source": []
  }
 ],
 "metadata": {
  "kernelspec": {
   "display_name": "Python 3",
   "language": "python",
   "name": "python3"
  },
  "language_info": {
   "codemirror_mode": {
    "name": "ipython",
    "version": 3
   },
   "file_extension": ".py",
   "mimetype": "text/x-python",
   "name": "python",
   "nbconvert_exporter": "python",
   "pygments_lexer": "ipython3",
   "version": "3.11.4"
  },
  "orig_nbformat": 4
 },
 "nbformat": 4,
 "nbformat_minor": 2
}
