{
 "cells": [
  {
   "cell_type": "code",
   "execution_count": 1,
   "metadata": {},
   "outputs": [],
   "source": [
    "import numpy as np\n",
    "import tensorflow as tf\n",
    "import matplotlib.pyplot as plt\n",
    "from tensorflow.keras.applications.mobilenet import preprocess_input\n",
    "from tensorflow.keras.models import Model\n",
    "from tensorflow.keras.preprocessing import image\n",
    "import matplotlib.pyplot as plt\n",
    "from tensorflow.keras.preprocessing.image import ImageDataGenerator\n",
    "from keras.models import load_model\n",
    "import os"
   ]
  },
  {
   "cell_type": "code",
   "execution_count": 2,
   "metadata": {},
   "outputs": [],
   "source": [
    "model = load_model(r'D:\\faces\\model\\model.h5')"
   ]
  },
  {
   "cell_type": "code",
   "execution_count": 3,
   "metadata": {},
   "outputs": [],
   "source": [
    "IMG_SIZE = 224\n",
    "TEST_DIR = r'D:\\faces\\three_faces\\validation_dataset'\n",
    "TEST_BATCH_SIZE = 8"
   ]
  },
  {
   "cell_type": "code",
   "execution_count": 4,
   "metadata": {},
   "outputs": [
    {
     "name": "stdout",
     "output_type": "stream",
     "text": [
      "Found 30 images belonging to 2 classes.\n",
      "<keras.preprocessing.image.DirectoryIterator object at 0x0000024626862E90>\n"
     ]
    }
   ],
   "source": [
    "test_datagen = ImageDataGenerator(preprocessing_function=preprocess_input)\n",
    "test_generator = test_datagen.flow_from_directory(\n",
    "    TEST_DIR,\n",
    "    target_size=(IMG_SIZE, IMG_SIZE),\n",
    "    batch_size = TEST_BATCH_SIZE,\n",
    "    shuffle=False,\n",
    "    class_mode='categorical'\n",
    ")\n",
    "ground_truth = test_generator.classes\n",
    "print(test_generator)"
   ]
  },
  {
   "cell_type": "code",
   "execution_count": 5,
   "metadata": {},
   "outputs": [
    {
     "name": "stderr",
     "output_type": "stream",
     "text": [
      "C:\\Users\\user\\AppData\\Local\\Temp\\ipykernel_8844\\1940690860.py:9: UserWarning: `Model.predict_generator` is deprecated and will be removed in a future version. Please use `Model.predict`, which supports generators.\n",
      "  predictions = model.predict_generator(test_generator, steps=len(test_generator))\n"
     ]
    }
   ],
   "source": [
    "def elon_or_gates(prediction):\n",
    "    if prediction[0] < prediction[1]:\n",
    "        return \"Elon Musk\"\n",
    "    else:\n",
    "        return \"Bill Gates\"\n",
    "\n",
    "\n",
    "\n",
    "predictions = model.predict_generator(test_generator, steps=len(test_generator))"
   ]
  },
  {
   "cell_type": "code",
   "execution_count": null,
   "metadata": {},
   "outputs": [],
   "source": [
    "for i in range(len(test_generator)):\n",
    "    for j in range(TEST_BATCH_SIZE):\n",
    "        index = i * TEST_BATCH_SIZE + j\n",
    "        if index < len(predictions):\n",
    "            prediction = predictions[index]\n",
    "            image_path = test_generator.filepaths[index]\n",
    "            img = image.load_img(image_path, target_size=(IMG_SIZE, IMG_SIZE))\n",
    "            img_array = image.img_to_array(img)\n",
    "            plt.imshow(img_array.astype(int))\n",
    "            percent = np.max(prediction) * 100\n",
    "            plt.title(f\"{elon_or_gates(prediction)}, {percent:2f}%\")\n",
    "            plt.show()"
   ]
  },
  {
   "cell_type": "code",
   "execution_count": 24,
   "metadata": {},
   "outputs": [
    {
     "ename": "InvalidArgumentError",
     "evalue": "Graph execution error:\n\nDetected at node 'model/mobilenet_1.00_224/conv1_relu/Relu6' defined at (most recent call last):\n    File \"<frozen runpy>\", line 198, in _run_module_as_main\n    File \"<frozen runpy>\", line 88, in _run_code\n    File \"C:\\Users\\user\\AppData\\Roaming\\Python\\Python311\\site-packages\\ipykernel_launcher.py\", line 17, in <module>\n      app.launch_new_instance()\n    File \"C:\\Users\\user\\AppData\\Roaming\\Python\\Python311\\site-packages\\traitlets\\config\\application.py\", line 1043, in launch_instance\n      app.start()\n    File \"C:\\Users\\user\\AppData\\Roaming\\Python\\Python311\\site-packages\\ipykernel\\kernelapp.py\", line 736, in start\n      self.io_loop.start()\n    File \"C:\\Users\\user\\AppData\\Roaming\\Python\\Python311\\site-packages\\tornado\\platform\\asyncio.py\", line 195, in start\n      self.asyncio_loop.run_forever()\n    File \"c:\\Users\\user\\AppData\\Local\\Programs\\Python\\Python311\\Lib\\asyncio\\base_events.py\", line 607, in run_forever\n      self._run_once()\n    File \"c:\\Users\\user\\AppData\\Local\\Programs\\Python\\Python311\\Lib\\asyncio\\base_events.py\", line 1922, in _run_once\n      handle._run()\n    File \"c:\\Users\\user\\AppData\\Local\\Programs\\Python\\Python311\\Lib\\asyncio\\events.py\", line 80, in _run\n      self._context.run(self._callback, *self._args)\n    File \"C:\\Users\\user\\AppData\\Roaming\\Python\\Python311\\site-packages\\ipykernel\\kernelbase.py\", line 516, in dispatch_queue\n      await self.process_one()\n    File \"C:\\Users\\user\\AppData\\Roaming\\Python\\Python311\\site-packages\\ipykernel\\kernelbase.py\", line 505, in process_one\n      await dispatch(*args)\n    File \"C:\\Users\\user\\AppData\\Roaming\\Python\\Python311\\site-packages\\ipykernel\\kernelbase.py\", line 412, in dispatch_shell\n      await result\n    File \"C:\\Users\\user\\AppData\\Roaming\\Python\\Python311\\site-packages\\ipykernel\\kernelbase.py\", line 740, in execute_request\n      reply_content = await reply_content\n    File \"C:\\Users\\user\\AppData\\Roaming\\Python\\Python311\\site-packages\\ipykernel\\ipkernel.py\", line 422, in do_execute\n      res = shell.run_cell(\n    File \"C:\\Users\\user\\AppData\\Roaming\\Python\\Python311\\site-packages\\ipykernel\\zmqshell.py\", line 546, in run_cell\n      return super().run_cell(*args, **kwargs)\n    File \"C:\\Users\\user\\AppData\\Roaming\\Python\\Python311\\site-packages\\IPython\\core\\interactiveshell.py\", line 3009, in run_cell\n      result = self._run_cell(\n    File \"C:\\Users\\user\\AppData\\Roaming\\Python\\Python311\\site-packages\\IPython\\core\\interactiveshell.py\", line 3064, in _run_cell\n      result = runner(coro)\n    File \"C:\\Users\\user\\AppData\\Roaming\\Python\\Python311\\site-packages\\IPython\\core\\async_helpers.py\", line 129, in _pseudo_sync_runner\n      coro.send(None)\n    File \"C:\\Users\\user\\AppData\\Roaming\\Python\\Python311\\site-packages\\IPython\\core\\interactiveshell.py\", line 3269, in run_cell_async\n      has_raised = await self.run_ast_nodes(code_ast.body, cell_name,\n    File \"C:\\Users\\user\\AppData\\Roaming\\Python\\Python311\\site-packages\\IPython\\core\\interactiveshell.py\", line 3448, in run_ast_nodes\n      if await self.run_code(code, result, async_=asy):\n    File \"C:\\Users\\user\\AppData\\Roaming\\Python\\Python311\\site-packages\\IPython\\core\\interactiveshell.py\", line 3508, in run_code\n      exec(code_obj, self.user_global_ns, self.user_ns)\n    File \"C:\\Users\\user\\AppData\\Local\\Temp\\ipykernel_8844\\1268849144.py\", line 6, in <module>\n      prediction = model.predict(img_array)\n    File \"c:\\Users\\user\\AppData\\Local\\Programs\\Python\\Python311\\Lib\\site-packages\\keras\\utils\\traceback_utils.py\", line 65, in error_handler\n      return fn(*args, **kwargs)\n    File \"c:\\Users\\user\\AppData\\Local\\Programs\\Python\\Python311\\Lib\\site-packages\\keras\\engine\\training.py\", line 2382, in predict\n      tmp_batch_outputs = self.predict_function(iterator)\n    File \"c:\\Users\\user\\AppData\\Local\\Programs\\Python\\Python311\\Lib\\site-packages\\keras\\engine\\training.py\", line 2169, in predict_function\n      return step_function(self, iterator)\n    File \"c:\\Users\\user\\AppData\\Local\\Programs\\Python\\Python311\\Lib\\site-packages\\keras\\engine\\training.py\", line 2155, in step_function\n      outputs = model.distribute_strategy.run(run_step, args=(data,))\n    File \"c:\\Users\\user\\AppData\\Local\\Programs\\Python\\Python311\\Lib\\site-packages\\keras\\engine\\training.py\", line 2143, in run_step\n      outputs = model.predict_step(data)\n    File \"c:\\Users\\user\\AppData\\Local\\Programs\\Python\\Python311\\Lib\\site-packages\\keras\\engine\\training.py\", line 2111, in predict_step\n      return self(x, training=False)\n    File \"c:\\Users\\user\\AppData\\Local\\Programs\\Python\\Python311\\Lib\\site-packages\\keras\\utils\\traceback_utils.py\", line 65, in error_handler\n      return fn(*args, **kwargs)\n    File \"c:\\Users\\user\\AppData\\Local\\Programs\\Python\\Python311\\Lib\\site-packages\\keras\\engine\\training.py\", line 558, in __call__\n      return super().__call__(*args, **kwargs)\n    File \"c:\\Users\\user\\AppData\\Local\\Programs\\Python\\Python311\\Lib\\site-packages\\keras\\utils\\traceback_utils.py\", line 65, in error_handler\n      return fn(*args, **kwargs)\n    File \"c:\\Users\\user\\AppData\\Local\\Programs\\Python\\Python311\\Lib\\site-packages\\keras\\engine\\base_layer.py\", line 1145, in __call__\n      outputs = call_fn(inputs, *args, **kwargs)\n    File \"c:\\Users\\user\\AppData\\Local\\Programs\\Python\\Python311\\Lib\\site-packages\\keras\\utils\\traceback_utils.py\", line 96, in error_handler\n      return fn(*args, **kwargs)\n    File \"c:\\Users\\user\\AppData\\Local\\Programs\\Python\\Python311\\Lib\\site-packages\\keras\\engine\\functional.py\", line 512, in call\n      return self._run_internal_graph(inputs, training=training, mask=mask)\n    File \"c:\\Users\\user\\AppData\\Local\\Programs\\Python\\Python311\\Lib\\site-packages\\keras\\engine\\functional.py\", line 669, in _run_internal_graph\n      outputs = node.layer(*args, **kwargs)\n    File \"c:\\Users\\user\\AppData\\Local\\Programs\\Python\\Python311\\Lib\\site-packages\\keras\\utils\\traceback_utils.py\", line 65, in error_handler\n      return fn(*args, **kwargs)\n    File \"c:\\Users\\user\\AppData\\Local\\Programs\\Python\\Python311\\Lib\\site-packages\\keras\\engine\\training.py\", line 558, in __call__\n      return super().__call__(*args, **kwargs)\n    File \"c:\\Users\\user\\AppData\\Local\\Programs\\Python\\Python311\\Lib\\site-packages\\keras\\utils\\traceback_utils.py\", line 65, in error_handler\n      return fn(*args, **kwargs)\n    File \"c:\\Users\\user\\AppData\\Local\\Programs\\Python\\Python311\\Lib\\site-packages\\keras\\engine\\base_layer.py\", line 1145, in __call__\n      outputs = call_fn(inputs, *args, **kwargs)\n    File \"c:\\Users\\user\\AppData\\Local\\Programs\\Python\\Python311\\Lib\\site-packages\\keras\\utils\\traceback_utils.py\", line 96, in error_handler\n      return fn(*args, **kwargs)\n    File \"c:\\Users\\user\\AppData\\Local\\Programs\\Python\\Python311\\Lib\\site-packages\\keras\\engine\\functional.py\", line 512, in call\n      return self._run_internal_graph(inputs, training=training, mask=mask)\n    File \"c:\\Users\\user\\AppData\\Local\\Programs\\Python\\Python311\\Lib\\site-packages\\keras\\engine\\functional.py\", line 669, in _run_internal_graph\n      outputs = node.layer(*args, **kwargs)\n    File \"c:\\Users\\user\\AppData\\Local\\Programs\\Python\\Python311\\Lib\\site-packages\\keras\\utils\\traceback_utils.py\", line 65, in error_handler\n      return fn(*args, **kwargs)\n    File \"c:\\Users\\user\\AppData\\Local\\Programs\\Python\\Python311\\Lib\\site-packages\\keras\\engine\\base_layer.py\", line 1145, in __call__\n      outputs = call_fn(inputs, *args, **kwargs)\n    File \"c:\\Users\\user\\AppData\\Local\\Programs\\Python\\Python311\\Lib\\site-packages\\keras\\utils\\traceback_utils.py\", line 96, in error_handler\n      return fn(*args, **kwargs)\n    File \"c:\\Users\\user\\AppData\\Local\\Programs\\Python\\Python311\\Lib\\site-packages\\keras\\layers\\activation\\relu.py\", line 105, in call\n      return backend.relu(\n    File \"c:\\Users\\user\\AppData\\Local\\Programs\\Python\\Python311\\Lib\\site-packages\\keras\\backend.py\", line 5393, in relu\n      x = tf.nn.relu6(x)\nNode: 'model/mobilenet_1.00_224/conv1_relu/Relu6'\nconvolution input must be 4-dimensional: [32,224,3]\n\t [[{{node model/mobilenet_1.00_224/conv1_relu/Relu6}}]] [Op:__inference_predict_function_4243]",
     "output_type": "error",
     "traceback": [
      "\u001b[1;31m---------------------------------------------------------------------------\u001b[0m",
      "\u001b[1;31mInvalidArgumentError\u001b[0m                      Traceback (most recent call last)",
      "Cell \u001b[1;32mIn[24], line 5\u001b[0m\n\u001b[0;32m      2\u001b[0m img \u001b[39m=\u001b[39m image\u001b[39m.\u001b[39mload_img(img_path, target_size\u001b[39m=\u001b[39m(IMG_SIZE, IMG_SIZE))\n\u001b[0;32m      3\u001b[0m img_array \u001b[39m=\u001b[39m image\u001b[39m.\u001b[39mimg_to_array(img)\n\u001b[1;32m----> 5\u001b[0m prediction \u001b[39m=\u001b[39m model\u001b[39m.\u001b[39;49mpredict(img_array)\n\u001b[0;32m      6\u001b[0m img_array_rescaled \u001b[39m=\u001b[39m (img_array[\u001b[39m0\u001b[39m] \u001b[39m+\u001b[39m \u001b[39m1\u001b[39m) \u001b[39m/\u001b[39m \u001b[39m2.0\u001b[39m\n\u001b[0;32m      7\u001b[0m percent \u001b[39m=\u001b[39m np\u001b[39m.\u001b[39margmax(prediction) \u001b[39m*\u001b[39m \u001b[39m100\u001b[39m\n",
      "File \u001b[1;32mc:\\Users\\user\\AppData\\Local\\Programs\\Python\\Python311\\Lib\\site-packages\\keras\\utils\\traceback_utils.py:70\u001b[0m, in \u001b[0;36mfilter_traceback.<locals>.error_handler\u001b[1;34m(*args, **kwargs)\u001b[0m\n\u001b[0;32m     67\u001b[0m     filtered_tb \u001b[39m=\u001b[39m _process_traceback_frames(e\u001b[39m.\u001b[39m__traceback__)\n\u001b[0;32m     68\u001b[0m     \u001b[39m# To get the full stack trace, call:\u001b[39;00m\n\u001b[0;32m     69\u001b[0m     \u001b[39m# `tf.debugging.disable_traceback_filtering()`\u001b[39;00m\n\u001b[1;32m---> 70\u001b[0m     \u001b[39mraise\u001b[39;00m e\u001b[39m.\u001b[39mwith_traceback(filtered_tb) \u001b[39mfrom\u001b[39;00m \u001b[39mNone\u001b[39;00m\n\u001b[0;32m     71\u001b[0m \u001b[39mfinally\u001b[39;00m:\n\u001b[0;32m     72\u001b[0m     \u001b[39mdel\u001b[39;00m filtered_tb\n",
      "File \u001b[1;32mc:\\Users\\user\\AppData\\Local\\Programs\\Python\\Python311\\Lib\\site-packages\\tensorflow\\python\\eager\\execute.py:52\u001b[0m, in \u001b[0;36mquick_execute\u001b[1;34m(op_name, num_outputs, inputs, attrs, ctx, name)\u001b[0m\n\u001b[0;32m     50\u001b[0m \u001b[39mtry\u001b[39;00m:\n\u001b[0;32m     51\u001b[0m   ctx\u001b[39m.\u001b[39mensure_initialized()\n\u001b[1;32m---> 52\u001b[0m   tensors \u001b[39m=\u001b[39m pywrap_tfe\u001b[39m.\u001b[39mTFE_Py_Execute(ctx\u001b[39m.\u001b[39m_handle, device_name, op_name,\n\u001b[0;32m     53\u001b[0m                                       inputs, attrs, num_outputs)\n\u001b[0;32m     54\u001b[0m \u001b[39mexcept\u001b[39;00m core\u001b[39m.\u001b[39m_NotOkStatusException \u001b[39mas\u001b[39;00m e:\n\u001b[0;32m     55\u001b[0m   \u001b[39mif\u001b[39;00m name \u001b[39mis\u001b[39;00m \u001b[39mnot\u001b[39;00m \u001b[39mNone\u001b[39;00m:\n",
      "\u001b[1;31mInvalidArgumentError\u001b[0m: Graph execution error:\n\nDetected at node 'model/mobilenet_1.00_224/conv1_relu/Relu6' defined at (most recent call last):\n    File \"<frozen runpy>\", line 198, in _run_module_as_main\n    File \"<frozen runpy>\", line 88, in _run_code\n    File \"C:\\Users\\user\\AppData\\Roaming\\Python\\Python311\\site-packages\\ipykernel_launcher.py\", line 17, in <module>\n      app.launch_new_instance()\n    File \"C:\\Users\\user\\AppData\\Roaming\\Python\\Python311\\site-packages\\traitlets\\config\\application.py\", line 1043, in launch_instance\n      app.start()\n    File \"C:\\Users\\user\\AppData\\Roaming\\Python\\Python311\\site-packages\\ipykernel\\kernelapp.py\", line 736, in start\n      self.io_loop.start()\n    File \"C:\\Users\\user\\AppData\\Roaming\\Python\\Python311\\site-packages\\tornado\\platform\\asyncio.py\", line 195, in start\n      self.asyncio_loop.run_forever()\n    File \"c:\\Users\\user\\AppData\\Local\\Programs\\Python\\Python311\\Lib\\asyncio\\base_events.py\", line 607, in run_forever\n      self._run_once()\n    File \"c:\\Users\\user\\AppData\\Local\\Programs\\Python\\Python311\\Lib\\asyncio\\base_events.py\", line 1922, in _run_once\n      handle._run()\n    File \"c:\\Users\\user\\AppData\\Local\\Programs\\Python\\Python311\\Lib\\asyncio\\events.py\", line 80, in _run\n      self._context.run(self._callback, *self._args)\n    File \"C:\\Users\\user\\AppData\\Roaming\\Python\\Python311\\site-packages\\ipykernel\\kernelbase.py\", line 516, in dispatch_queue\n      await self.process_one()\n    File \"C:\\Users\\user\\AppData\\Roaming\\Python\\Python311\\site-packages\\ipykernel\\kernelbase.py\", line 505, in process_one\n      await dispatch(*args)\n    File \"C:\\Users\\user\\AppData\\Roaming\\Python\\Python311\\site-packages\\ipykernel\\kernelbase.py\", line 412, in dispatch_shell\n      await result\n    File \"C:\\Users\\user\\AppData\\Roaming\\Python\\Python311\\site-packages\\ipykernel\\kernelbase.py\", line 740, in execute_request\n      reply_content = await reply_content\n    File \"C:\\Users\\user\\AppData\\Roaming\\Python\\Python311\\site-packages\\ipykernel\\ipkernel.py\", line 422, in do_execute\n      res = shell.run_cell(\n    File \"C:\\Users\\user\\AppData\\Roaming\\Python\\Python311\\site-packages\\ipykernel\\zmqshell.py\", line 546, in run_cell\n      return super().run_cell(*args, **kwargs)\n    File \"C:\\Users\\user\\AppData\\Roaming\\Python\\Python311\\site-packages\\IPython\\core\\interactiveshell.py\", line 3009, in run_cell\n      result = self._run_cell(\n    File \"C:\\Users\\user\\AppData\\Roaming\\Python\\Python311\\site-packages\\IPython\\core\\interactiveshell.py\", line 3064, in _run_cell\n      result = runner(coro)\n    File \"C:\\Users\\user\\AppData\\Roaming\\Python\\Python311\\site-packages\\IPython\\core\\async_helpers.py\", line 129, in _pseudo_sync_runner\n      coro.send(None)\n    File \"C:\\Users\\user\\AppData\\Roaming\\Python\\Python311\\site-packages\\IPython\\core\\interactiveshell.py\", line 3269, in run_cell_async\n      has_raised = await self.run_ast_nodes(code_ast.body, cell_name,\n    File \"C:\\Users\\user\\AppData\\Roaming\\Python\\Python311\\site-packages\\IPython\\core\\interactiveshell.py\", line 3448, in run_ast_nodes\n      if await self.run_code(code, result, async_=asy):\n    File \"C:\\Users\\user\\AppData\\Roaming\\Python\\Python311\\site-packages\\IPython\\core\\interactiveshell.py\", line 3508, in run_code\n      exec(code_obj, self.user_global_ns, self.user_ns)\n    File \"C:\\Users\\user\\AppData\\Local\\Temp\\ipykernel_8844\\1268849144.py\", line 6, in <module>\n      prediction = model.predict(img_array)\n    File \"c:\\Users\\user\\AppData\\Local\\Programs\\Python\\Python311\\Lib\\site-packages\\keras\\utils\\traceback_utils.py\", line 65, in error_handler\n      return fn(*args, **kwargs)\n    File \"c:\\Users\\user\\AppData\\Local\\Programs\\Python\\Python311\\Lib\\site-packages\\keras\\engine\\training.py\", line 2382, in predict\n      tmp_batch_outputs = self.predict_function(iterator)\n    File \"c:\\Users\\user\\AppData\\Local\\Programs\\Python\\Python311\\Lib\\site-packages\\keras\\engine\\training.py\", line 2169, in predict_function\n      return step_function(self, iterator)\n    File \"c:\\Users\\user\\AppData\\Local\\Programs\\Python\\Python311\\Lib\\site-packages\\keras\\engine\\training.py\", line 2155, in step_function\n      outputs = model.distribute_strategy.run(run_step, args=(data,))\n    File \"c:\\Users\\user\\AppData\\Local\\Programs\\Python\\Python311\\Lib\\site-packages\\keras\\engine\\training.py\", line 2143, in run_step\n      outputs = model.predict_step(data)\n    File \"c:\\Users\\user\\AppData\\Local\\Programs\\Python\\Python311\\Lib\\site-packages\\keras\\engine\\training.py\", line 2111, in predict_step\n      return self(x, training=False)\n    File \"c:\\Users\\user\\AppData\\Local\\Programs\\Python\\Python311\\Lib\\site-packages\\keras\\utils\\traceback_utils.py\", line 65, in error_handler\n      return fn(*args, **kwargs)\n    File \"c:\\Users\\user\\AppData\\Local\\Programs\\Python\\Python311\\Lib\\site-packages\\keras\\engine\\training.py\", line 558, in __call__\n      return super().__call__(*args, **kwargs)\n    File \"c:\\Users\\user\\AppData\\Local\\Programs\\Python\\Python311\\Lib\\site-packages\\keras\\utils\\traceback_utils.py\", line 65, in error_handler\n      return fn(*args, **kwargs)\n    File \"c:\\Users\\user\\AppData\\Local\\Programs\\Python\\Python311\\Lib\\site-packages\\keras\\engine\\base_layer.py\", line 1145, in __call__\n      outputs = call_fn(inputs, *args, **kwargs)\n    File \"c:\\Users\\user\\AppData\\Local\\Programs\\Python\\Python311\\Lib\\site-packages\\keras\\utils\\traceback_utils.py\", line 96, in error_handler\n      return fn(*args, **kwargs)\n    File \"c:\\Users\\user\\AppData\\Local\\Programs\\Python\\Python311\\Lib\\site-packages\\keras\\engine\\functional.py\", line 512, in call\n      return self._run_internal_graph(inputs, training=training, mask=mask)\n    File \"c:\\Users\\user\\AppData\\Local\\Programs\\Python\\Python311\\Lib\\site-packages\\keras\\engine\\functional.py\", line 669, in _run_internal_graph\n      outputs = node.layer(*args, **kwargs)\n    File \"c:\\Users\\user\\AppData\\Local\\Programs\\Python\\Python311\\Lib\\site-packages\\keras\\utils\\traceback_utils.py\", line 65, in error_handler\n      return fn(*args, **kwargs)\n    File \"c:\\Users\\user\\AppData\\Local\\Programs\\Python\\Python311\\Lib\\site-packages\\keras\\engine\\training.py\", line 558, in __call__\n      return super().__call__(*args, **kwargs)\n    File \"c:\\Users\\user\\AppData\\Local\\Programs\\Python\\Python311\\Lib\\site-packages\\keras\\utils\\traceback_utils.py\", line 65, in error_handler\n      return fn(*args, **kwargs)\n    File \"c:\\Users\\user\\AppData\\Local\\Programs\\Python\\Python311\\Lib\\site-packages\\keras\\engine\\base_layer.py\", line 1145, in __call__\n      outputs = call_fn(inputs, *args, **kwargs)\n    File \"c:\\Users\\user\\AppData\\Local\\Programs\\Python\\Python311\\Lib\\site-packages\\keras\\utils\\traceback_utils.py\", line 96, in error_handler\n      return fn(*args, **kwargs)\n    File \"c:\\Users\\user\\AppData\\Local\\Programs\\Python\\Python311\\Lib\\site-packages\\keras\\engine\\functional.py\", line 512, in call\n      return self._run_internal_graph(inputs, training=training, mask=mask)\n    File \"c:\\Users\\user\\AppData\\Local\\Programs\\Python\\Python311\\Lib\\site-packages\\keras\\engine\\functional.py\", line 669, in _run_internal_graph\n      outputs = node.layer(*args, **kwargs)\n    File \"c:\\Users\\user\\AppData\\Local\\Programs\\Python\\Python311\\Lib\\site-packages\\keras\\utils\\traceback_utils.py\", line 65, in error_handler\n      return fn(*args, **kwargs)\n    File \"c:\\Users\\user\\AppData\\Local\\Programs\\Python\\Python311\\Lib\\site-packages\\keras\\engine\\base_layer.py\", line 1145, in __call__\n      outputs = call_fn(inputs, *args, **kwargs)\n    File \"c:\\Users\\user\\AppData\\Local\\Programs\\Python\\Python311\\Lib\\site-packages\\keras\\utils\\traceback_utils.py\", line 96, in error_handler\n      return fn(*args, **kwargs)\n    File \"c:\\Users\\user\\AppData\\Local\\Programs\\Python\\Python311\\Lib\\site-packages\\keras\\layers\\activation\\relu.py\", line 105, in call\n      return backend.relu(\n    File \"c:\\Users\\user\\AppData\\Local\\Programs\\Python\\Python311\\Lib\\site-packages\\keras\\backend.py\", line 5393, in relu\n      x = tf.nn.relu6(x)\nNode: 'model/mobilenet_1.00_224/conv1_relu/Relu6'\nconvolution input must be 4-dimensional: [32,224,3]\n\t [[{{node model/mobilenet_1.00_224/conv1_relu/Relu6}}]] [Op:__inference_predict_function_4243]"
     ]
    }
   ],
   "source": []
  },
  {
   "cell_type": "code",
   "execution_count": null,
   "metadata": {},
   "outputs": [],
   "source": []
  },
  {
   "cell_type": "code",
   "execution_count": null,
   "metadata": {},
   "outputs": [],
   "source": []
  },
  {
   "cell_type": "code",
   "execution_count": null,
   "metadata": {},
   "outputs": [],
   "source": []
  }
 ],
 "metadata": {
  "kernelspec": {
   "display_name": "Python 3",
   "language": "python",
   "name": "python3"
  },
  "language_info": {
   "codemirror_mode": {
    "name": "ipython",
    "version": 3
   },
   "file_extension": ".py",
   "mimetype": "text/x-python",
   "name": "python",
   "nbconvert_exporter": "python",
   "pygments_lexer": "ipython3",
   "version": "3.11.4"
  },
  "orig_nbformat": 4
 },
 "nbformat": 4,
 "nbformat_minor": 2
}
